File: qpd-calibration/data/Example-Stress-Calibration.csv
Deflection (degrees),Stress (MPa)
0,0
0.2,25
0.4,50
0.6,75
0.8,100
1,125
1.2,150
1.4,175
1.6,200
1.8,225
2,250
2.2,275
2.4,300
2.6,325
2.8,350
3,375
3.2,400
3.4,425
3.6,-1
3.8,-1
4,-1